2020-12-22 20:54:19,021ERROR:Exception on /reset_password_request [POST][in/Library/Frameworks/Python.framework/Versions/3.8/lib/python3.8/site-packages/flask/app.py:1891]
Traceback (most recent call last):
  File "/Library/Frameworks/Python.framework/Versions/3.8/lib/python3.8/site-packages/flask/app.py", line 2447, in wsgi_app
    response = self.full_dispatch_request()
  File "/Library/Frameworks/Python.framework/Versions/3.8/lib/python3.8/site-packages/flask/app.py", line 1952, in full_dispatch_request
    rv = self.handle_user_exception(e)
  File "/Library/Frameworks/Python.framework/Versions/3.8/lib/python3.8/site-packages/flask/app.py", line 1821, in handle_user_exception
    reraise(exc_type, exc_value, tb)
  File "/Library/Frameworks/Python.framework/Versions/3.8/lib/python3.8/site-packages/flask/_compat.py", line 39, in reraise
    raise value
  File "/Library/Frameworks/Python.framework/Versions/3.8/lib/python3.8/site-packages/flask/app.py", line 1950, in full_dispatch_request
    rv = self.dispatch_request()
  File "/Library/Frameworks/Python.framework/Versions/3.8/lib/python3.8/site-packages/flask/app.py", line 1936, in dispatch_request
    return self.view_functions[rule.endpoint](**req.view_args)
  File "/Users/louisgreen/Documents/microblog/app/routes.py", line 153, in reset_password_request
    send_password_reset_email(user)
  File "/Users/louisgreen/Documents/microblog/app/email.py", line 13, in send_password_reset_email
    token = user.get_reset_password_token()
  File "/Users/louisgreen/Documents/microblog/app/models.py", line 58, in get_reset_password_token
    {'reset_password': self.id, 'exp':time()+ expires_in}, app.config['SECRET_KEY'], algorithm='HS256').decode('utf-8')
NameError: name 'time' is not defined
2020-12-22 20:54:41,599ERROR:Exception on /reset_password_request [POST][in/Library/Frameworks/Python.framework/Versions/3.8/lib/python3.8/site-packages/flask/app.py:1891]
Traceback (most recent call last):
  File "/Library/Frameworks/Python.framework/Versions/3.8/lib/python3.8/site-packages/flask/app.py", line 2447, in wsgi_app
    response = self.full_dispatch_request()
  File "/Library/Frameworks/Python.framework/Versions/3.8/lib/python3.8/site-packages/flask/app.py", line 1952, in full_dispatch_request
    rv = self.handle_user_exception(e)
  File "/Library/Frameworks/Python.framework/Versions/3.8/lib/python3.8/site-packages/flask/app.py", line 1821, in handle_user_exception
    reraise(exc_type, exc_value, tb)
  File "/Library/Frameworks/Python.framework/Versions/3.8/lib/python3.8/site-packages/flask/_compat.py", line 39, in reraise
    raise value
  File "/Library/Frameworks/Python.framework/Versions/3.8/lib/python3.8/site-packages/flask/app.py", line 1950, in full_dispatch_request
    rv = self.dispatch_request()
  File "/Library/Frameworks/Python.framework/Versions/3.8/lib/python3.8/site-packages/flask/app.py", line 1936, in dispatch_request
    return self.view_functions[rule.endpoint](**req.view_args)
  File "/Users/louisgreen/Documents/microblog/app/routes.py", line 153, in reset_password_request
    send_password_reset_email(user)
  File "/Users/louisgreen/Documents/microblog/app/email.py", line 13, in send_password_reset_email
    token = user.get_reset_password_token()
  File "/Users/louisgreen/Documents/microblog/app/models.py", line 58, in get_reset_password_token
    return jwt.encode(
NameError: name 'time' is not defined
2020-12-22 20:54:54,508INFO:Microblog startup[in/Users/louisgreen/Documents/microblog/app/__init__.py:45]
2020-12-22 20:54:56,289INFO:Microblog startup[in/Users/louisgreen/Documents/microblog/app/__init__.py:45]
2020-12-22 20:55:00,918ERROR:Exception on /reset_password_request [POST][in/Library/Frameworks/Python.framework/Versions/3.8/lib/python3.8/site-packages/flask/app.py:1891]
Traceback (most recent call last):
  File "/Library/Frameworks/Python.framework/Versions/3.8/lib/python3.8/site-packages/flask/app.py", line 2447, in wsgi_app
    response = self.full_dispatch_request()
  File "/Library/Frameworks/Python.framework/Versions/3.8/lib/python3.8/site-packages/flask/app.py", line 1952, in full_dispatch_request
    rv = self.handle_user_exception(e)
  File "/Library/Frameworks/Python.framework/Versions/3.8/lib/python3.8/site-packages/flask/app.py", line 1821, in handle_user_exception
    reraise(exc_type, exc_value, tb)
  File "/Library/Frameworks/Python.framework/Versions/3.8/lib/python3.8/site-packages/flask/_compat.py", line 39, in reraise
    raise value
  File "/Library/Frameworks/Python.framework/Versions/3.8/lib/python3.8/site-packages/flask/app.py", line 1950, in full_dispatch_request
    rv = self.dispatch_request()
  File "/Library/Frameworks/Python.framework/Versions/3.8/lib/python3.8/site-packages/flask/app.py", line 1936, in dispatch_request
    return self.view_functions[rule.endpoint](**req.view_args)
  File "/Users/louisgreen/Documents/microblog/app/routes.py", line 153, in reset_password_request
    send_password_reset_email(user)
  File "/Users/louisgreen/Documents/microblog/app/email.py", line 13, in send_password_reset_email
    token = user.get_reset_password_token()
  File "/Users/louisgreen/Documents/microblog/app/models.py", line 59, in get_reset_password_token
    {'reset_password': self.id, 'exp':time()+ expires_in}, app.config['SECRET_KEY'], algorithm='HS256').decode('utf-8')
NameError: name 'app' is not defined
2020-12-22 20:55:28,511ERROR:Exception on /reset_password_request [POST][in/Library/Frameworks/Python.framework/Versions/3.8/lib/python3.8/site-packages/flask/app.py:1891]
Traceback (most recent call last):
  File "/Library/Frameworks/Python.framework/Versions/3.8/lib/python3.8/site-packages/flask/app.py", line 2447, in wsgi_app
    response = self.full_dispatch_request()
  File "/Library/Frameworks/Python.framework/Versions/3.8/lib/python3.8/site-packages/flask/app.py", line 1952, in full_dispatch_request
    rv = self.handle_user_exception(e)
  File "/Library/Frameworks/Python.framework/Versions/3.8/lib/python3.8/site-packages/flask/app.py", line 1821, in handle_user_exception
    reraise(exc_type, exc_value, tb)
  File "/Library/Frameworks/Python.framework/Versions/3.8/lib/python3.8/site-packages/flask/_compat.py", line 39, in reraise
    raise value
  File "/Library/Frameworks/Python.framework/Versions/3.8/lib/python3.8/site-packages/flask/app.py", line 1950, in full_dispatch_request
    rv = self.dispatch_request()
  File "/Library/Frameworks/Python.framework/Versions/3.8/lib/python3.8/site-packages/flask/app.py", line 1936, in dispatch_request
    return self.view_functions[rule.endpoint](**req.view_args)
  File "/Users/louisgreen/Documents/microblog/app/routes.py", line 153, in reset_password_request
    send_password_reset_email(user)
  File "/Users/louisgreen/Documents/microblog/app/email.py", line 13, in send_password_reset_email
    token = user.get_reset_password_token()
  File "/Users/louisgreen/Documents/microblog/app/models.py", line 59, in get_reset_password_token
    return jwt.encode(
NameError: name 'app' is not defined
2020-12-22 20:55:34,080INFO:Microblog startup[in/Users/louisgreen/Documents/microblog/app/__init__.py:45]
2020-12-22 21:00:40,116INFO:Microblog startup[in/Users/louisgreen/Documents/microblog/app/__init__.py:45]
2020-12-22 21:04:42,513INFO:Microblog startup[in/Users/louisgreen/Documents/microblog/app/__init__.py:45]
