2020-12-20 14:16:03,733INFO:Microblog startup[in/Users/louisgreen/Documents/microblog/app/__init__.py:43]
2020-12-20 14:36:07,505INFO:Microblog startup[in/Users/louisgreen/Documents/microblog/app/__init__.py:43]
2020-12-20 14:36:13,350INFO:Microblog startup[in/Users/louisgreen/Documents/microblog/app/__init__.py:43]
2020-12-20 14:40:48,679INFO:Microblog startup[in/Users/louisgreen/Documents/microblog/app/__init__.py:43]
2020-12-20 14:41:02,106INFO:Microblog startup[in/Users/louisgreen/Documents/microblog/app/__init__.py:43]
2020-12-20 14:41:06,357INFO:Microblog startup[in/Users/louisgreen/Documents/microblog/app/__init__.py:43]
2020-12-21 11:22:33,302INFO:Microblog startup[in/Users/louisgreen/Documents/microblog/app/__init__.py:43]
2020-12-21 11:24:25,196INFO:Microblog startup[in/Users/louisgreen/Documents/microblog/app/__init__.py:43]
2020-12-21 11:25:16,329INFO:Microblog startup[in/Users/louisgreen/Documents/microblog/app/__init__.py:43]
2020-12-21 11:31:07,923INFO:Microblog startup[in/Users/louisgreen/Documents/microblog/app/__init__.py:43]
2020-12-21 11:32:07,488INFO:Microblog startup[in/Users/louisgreen/Documents/microblog/app/__init__.py:43]
2020-12-21 11:35:40,836INFO:Microblog startup[in/Users/louisgreen/Documents/microblog/app/__init__.py:43]
2020-12-21 11:36:53,861INFO:Microblog startup[in/Users/louisgreen/Documents/microblog/app/__init__.py:43]
2020-12-21 11:38:09,436INFO:Microblog startup[in/Users/louisgreen/Documents/microblog/app/__init__.py:43]
2020-12-21 11:38:50,701INFO:Microblog startup[in/Users/louisgreen/Documents/microblog/app/__init__.py:43]
2020-12-21 16:38:35,981INFO:Microblog startup[in/Users/louisgreen/Documents/microblog/app/__init__.py:43]
2020-12-21 16:38:41,943ERROR:Exception on / [GET][in/Library/Frameworks/Python.framework/Versions/3.8/lib/python3.8/site-packages/flask/app.py:1891]
Traceback (most recent call last):
  File "/Library/Frameworks/Python.framework/Versions/3.8/lib/python3.8/site-packages/sqlalchemy/sql/elements.py", line 747, in __getattr__
    return getattr(self.comparator, key)
AttributeError: 'Comparator' object has no attribute 'all'

The above exception was the direct cause of the following exception:

Traceback (most recent call last):
  File "/Library/Frameworks/Python.framework/Versions/3.8/lib/python3.8/site-packages/flask/app.py", line 2447, in wsgi_app
    response = self.full_dispatch_request()
  File "/Library/Frameworks/Python.framework/Versions/3.8/lib/python3.8/site-packages/flask/app.py", line 1952, in full_dispatch_request
    rv = self.handle_user_exception(e)
  File "/Library/Frameworks/Python.framework/Versions/3.8/lib/python3.8/site-packages/flask/app.py", line 1821, in handle_user_exception
    reraise(exc_type, exc_value, tb)
  File "/Library/Frameworks/Python.framework/Versions/3.8/lib/python3.8/site-packages/flask/_compat.py", line 39, in reraise
    raise value
  File "/Library/Frameworks/Python.framework/Versions/3.8/lib/python3.8/site-packages/flask/app.py", line 1950, in full_dispatch_request
    rv = self.dispatch_request()
  File "/Library/Frameworks/Python.framework/Versions/3.8/lib/python3.8/site-packages/flask/app.py", line 1936, in dispatch_request
    return self.view_functions[rule.endpoint](**req.view_args)
  File "/Library/Frameworks/Python.framework/Versions/3.8/lib/python3.8/site-packages/flask_login/utils.py", line 272, in decorated_view
    return func(*args, **kwargs)
  File "/Users/louisgreen/Documents/microblog/app/routes.py", line 23, in index
    posts = Post.query.order_by(Post.timestamp.desc().all()).paginate(
  File "/Library/Frameworks/Python.framework/Versions/3.8/lib/python3.8/site-packages/sqlalchemy/sql/elements.py", line 749, in __getattr__
    util.raise_(
  File "/Library/Frameworks/Python.framework/Versions/3.8/lib/python3.8/site-packages/sqlalchemy/util/compat.py", line 182, in raise_
    raise exception
AttributeError: Neither 'UnaryExpression' object nor 'Comparator' object has an attribute 'all'
2020-12-21 16:38:47,542ERROR:Exception on /index [GET][in/Library/Frameworks/Python.framework/Versions/3.8/lib/python3.8/site-packages/flask/app.py:1891]
Traceback (most recent call last):
  File "/Library/Frameworks/Python.framework/Versions/3.8/lib/python3.8/site-packages/sqlalchemy/sql/elements.py", line 747, in __getattr__
    return getattr(self.comparator, key)
AttributeError: 'Comparator' object has no attribute 'all'

The above exception was the direct cause of the following exception:

Traceback (most recent call last):
  File "/Library/Frameworks/Python.framework/Versions/3.8/lib/python3.8/site-packages/flask/app.py", line 2447, in wsgi_app
    response = self.full_dispatch_request()
  File "/Library/Frameworks/Python.framework/Versions/3.8/lib/python3.8/site-packages/flask/app.py", line 1952, in full_dispatch_request
    rv = self.handle_user_exception(e)
  File "/Library/Frameworks/Python.framework/Versions/3.8/lib/python3.8/site-packages/flask/app.py", line 1821, in handle_user_exception
    reraise(exc_type, exc_value, tb)
  File "/Library/Frameworks/Python.framework/Versions/3.8/lib/python3.8/site-packages/flask/_compat.py", line 39, in reraise
    raise value
  File "/Library/Frameworks/Python.framework/Versions/3.8/lib/python3.8/site-packages/flask/app.py", line 1950, in full_dispatch_request
    rv = self.dispatch_request()
  File "/Library/Frameworks/Python.framework/Versions/3.8/lib/python3.8/site-packages/flask/app.py", line 1936, in dispatch_request
    return self.view_functions[rule.endpoint](**req.view_args)
  File "/Library/Frameworks/Python.framework/Versions/3.8/lib/python3.8/site-packages/flask_login/utils.py", line 272, in decorated_view
    return func(*args, **kwargs)
  File "/Users/louisgreen/Documents/microblog/app/routes.py", line 23, in index
    posts = Post.query.order_by(Post.timestamp.desc().all()).paginate(
  File "/Library/Frameworks/Python.framework/Versions/3.8/lib/python3.8/site-packages/sqlalchemy/sql/elements.py", line 749, in __getattr__
    util.raise_(
  File "/Library/Frameworks/Python.framework/Versions/3.8/lib/python3.8/site-packages/sqlalchemy/util/compat.py", line 182, in raise_
    raise exception
AttributeError: Neither 'UnaryExpression' object nor 'Comparator' object has an attribute 'all'
2020-12-21 16:40:08,920INFO:Microblog startup[in/Users/louisgreen/Documents/microblog/app/__init__.py:43]
2020-12-21 16:40:12,255ERROR:Exception on /index [GET][in/Library/Frameworks/Python.framework/Versions/3.8/lib/python3.8/site-packages/flask/app.py:1891]
Traceback (most recent call last):
  File "/Library/Frameworks/Python.framework/Versions/3.8/lib/python3.8/site-packages/flask/app.py", line 2447, in wsgi_app
    response = self.full_dispatch_request()
  File "/Library/Frameworks/Python.framework/Versions/3.8/lib/python3.8/site-packages/flask/app.py", line 1952, in full_dispatch_request
    rv = self.handle_user_exception(e)
  File "/Library/Frameworks/Python.framework/Versions/3.8/lib/python3.8/site-packages/flask/app.py", line 1821, in handle_user_exception
    reraise(exc_type, exc_value, tb)
  File "/Library/Frameworks/Python.framework/Versions/3.8/lib/python3.8/site-packages/flask/_compat.py", line 39, in reraise
    raise value
  File "/Library/Frameworks/Python.framework/Versions/3.8/lib/python3.8/site-packages/flask/app.py", line 1950, in full_dispatch_request
    rv = self.dispatch_request()
  File "/Library/Frameworks/Python.framework/Versions/3.8/lib/python3.8/site-packages/flask/app.py", line 1936, in dispatch_request
    return self.view_functions[rule.endpoint](**req.view_args)
  File "/Library/Frameworks/Python.framework/Versions/3.8/lib/python3.8/site-packages/flask_login/utils.py", line 272, in decorated_view
    return func(*args, **kwargs)
  File "/Users/louisgreen/Documents/microblog/app/routes.py", line 25, in index
    return render_template('index.html', title = 'Home', form=form, posts = posts.items)
  File "/Library/Frameworks/Python.framework/Versions/3.8/lib/python3.8/site-packages/flask/templating.py", line 138, in render_template
    ctx.app.jinja_env.get_or_select_template(template_name_or_list),
  File "/Library/Frameworks/Python.framework/Versions/3.8/lib/python3.8/site-packages/jinja2/environment.py", line 930, in get_or_select_template
    return self.get_template(template_name_or_list, parent, globals)
  File "/Library/Frameworks/Python.framework/Versions/3.8/lib/python3.8/site-packages/jinja2/environment.py", line 883, in get_template
    return self._load_template(name, self.make_globals(globals))
  File "/Library/Frameworks/Python.framework/Versions/3.8/lib/python3.8/site-packages/jinja2/environment.py", line 857, in _load_template
    template = self.loader.load(self, name, globals)
  File "/Library/Frameworks/Python.framework/Versions/3.8/lib/python3.8/site-packages/jinja2/loaders.py", line 127, in load
    code = environment.compile(source, name, filename)
  File "/Library/Frameworks/Python.framework/Versions/3.8/lib/python3.8/site-packages/jinja2/environment.py", line 638, in compile
    self.handle_exception(source=source_hint)
  File "/Library/Frameworks/Python.framework/Versions/3.8/lib/python3.8/site-packages/jinja2/environment.py", line 832, in handle_exception
    reraise(*rewrite_traceback_stack(source=source))
  File "/Library/Frameworks/Python.framework/Versions/3.8/lib/python3.8/site-packages/jinja2/_compat.py", line 28, in reraise
    raise value.with_traceback(tb)
  File "/Users/louisgreen/Documents/microblog/app/templates/index.html", line 21, in template
    {% endfor %}
jinja2.exceptions.TemplateSyntaxError: Encountered unknown tag 'endfor'. Jinja was looking for the following tags: 'endblock'. The innermost block that needs to be closed is 'block'.
2020-12-21 16:42:02,641INFO:Microblog startup[in/Users/louisgreen/Documents/microblog/app/__init__.py:43]
